Workbook

Sheet Overview
B2: Retail Sales Analytics — Excel Portfolio
B3: Saideepak Ramarangula · Business Analytics with AI (Frontlines EduTech, live online programme) · 2026
B5: This workbook brings together my Excel work from the programme into one retail analytics project: a clean source dataset, a KPI dashboard with charts, and the formula techniques behind it — business-rule flags, customer segmentation, conditional totals, text cleaning and visual exception reporting. Everything is formula-driven, so changing the data updates every result.
B9: What's inside
B10: # | C10: Sheet (click to open) | D10: What it shows | E10: Excel skills
B11: 1 | C11: Dashboard | D11: KPIs, summary tables and 4 charts built on 150 retail orders | E11: SUMIFS, COUNTIFS, EOMONTH, RANK, charts
B12: 2 | C12: Retail_Data | D12: Clean source table of 150 orders with a calculated Revenue column | E12: Excel Tables, formulas
B13: 3 | C13: Cell_References | D13: GST calculator, target tracker and monthly tax grid | E13: Relative / absolute / mixed references
B14: 4 | C14: IF_Logic | D14: 20 business-rule columns on 10 sales invoices | E14: IF, AND, OR, nested IF
B15: 5 | C15: Nested_IF | D15: 20 multi-level segmentation rules on 15 customers | E15: Nested IF, AND, OR
B16: 6 | C16: SUMIF_COUNTIF | D16: 29 single- and multi-condition questions with live answers | E16: SUMIF, COUNTIF, SUMIFS, COUNTIFS
B17: 7 | C17: Text_Functions | D17: Cleaning and splitting 10 messy customer records | E17: TRIM, PROPER, LEFT/RIGHT/MID, FIND, TEXTJOIN …
B18: 8 | C18: Conditional_Formatting | D18: 35 orders with 8 visual rules + customer growth table | E18: Conditional formatting, icon sets, data bars
B20: Key findings from the dashboard
B21: • | C21: Electronics is the largest category at 47% of revenue — more than Fashion (11%) and Baby (16%) combined.
B22: • | C22: North is the weakest region (13% of revenue) — less than half of West (30%).
B23: • | C23: Revenue peaked in February and was lowest in June; the half-year is uneven rather than steadily growing.
B24: • | C24: The top two products (Laptop, Dining Table) bring in 44% of all revenue.
B26: How to read the sheets
C27: ■ Navy header = raw data ■ Green header = calculated with formulas
C28: Each module sheet ends with a table showing the business rule and the exact formula used.
C29: Yellow cells with blue text are inputs you can change (e.g. the GST rate).

Sheet Dashboard
A1: Retail Sales Dashboard — Jan to Jun 2026
A2: 150 retail orders summarised by category, region, channel, customer segment, month and product. Every number is a live formula on the Retail_Data sheet.
A3: Excel skills: SUMIFS, COUNTIFS, AVERAGE, EOMONTH, RANK, KPI design, bar / pie / line charts
B5: Total Revenue | D5: Orders | F5: Units Sold | H5: Avg Order Value | J5: Avg Discount
B6: =SUM(Retail_Data!$K$2:$K$151) -> 57052 | D6: =COUNTA(Retail_Data!$A$2:$A$151) -> 150 | F6: =SUM(Retail_Data!$H$2:$H$151) -> 428 | H6: =B6/D6 -> 380.34667 | J6: =AVERAGE(Retail_Data!$J$2:$J$151) -> 0.098
B8: Revenue by Category | G8: Revenue by Region
B9: Category | C9: Revenue | D9: Orders | E9: Share | G9: Region | H9: Revenue | I9: Orders | J9: Share
B10: Electronics | C10: =SUMIFS(Retail_Data!$K$2:$K$151,Retail_Data!$D$2:$D$151,$B10) -> 26943.5 | D10: =COUNTIFS(Retail_Data!$D$2:$D$151,$B10) -> 35 | E10: =C10/$B$6 -> 0.47226215 | G10: West | H10: =SUMIFS(Retail_Data!$K$2:$K$151,Retail_Data!$E$2:$E$151,$G10) -> 17327 | I10: =COUNTIFS(Retail_Data!$E$2:$E$151,$G10) -> 41 | J10: =H10/$B$6 -> 0.30370539
B11: Home | C11: =SUMIFS(Retail_Data!$K$2:$K$151,Retail_Data!$D$2:$D$151,$B11) -> 14743.25 | D11: =COUNTIFS(Retail_Data!$D$2:$D$151,$B11) -> 24 | E11: =C11/$B$6 -> 0.25841776 | G11: East | H11: =SUMIFS(Retail_Data!$K$2:$K$151,Retail_Data!$E$2:$E$151,$G11) -> 16635.75 | I11: =COUNTIFS(Retail_Data!$E$2:$E$151,$G11) -> 38 | J11: =H11/$B$6 -> 0.29158925
B12: Baby | C12: =SUMIFS(Retail_Data!$K$2:$K$151,Retail_Data!$D$2:$D$151,$B12) -> 8877.25 | D12: =COUNTIFS(Retail_Data!$D$2:$D$151,$B12) -> 44 | E12: =C12/$B$6 -> 0.15559928 | G12: South | H12: =SUMIFS(Retail_Data!$K$2:$K$151,Retail_Data!$E$2:$E$151,$G12) -> 15732.25 | I12: =COUNTIFS(Retail_Data!$E$2:$E$151,$G12) -> 39 | J12: =H12/$B$6 -> 0.27575282
B13: Fashion | C13: =SUMIFS(Retail_Data!$K$2:$K$151,Retail_Data!$D$2:$D$151,$B13) -> 6488 | D13: =COUNTIFS(Retail_Data!$D$2:$D$151,$B13) -> 47 | E13: =C13/$B$6 -> 0.11372082 | G13: North | H13: =SUMIFS(Retail_Data!$K$2:$K$151,Retail_Data!$E$2:$E$151,$G13) -> 7357 | I13: =COUNTIFS(Retail_Data!$E$2:$E$151,$G13) -> 32 | J13: =H13/$B$6 -> 0.12895253
B14: Total | C14: =SUM(C10:C13) -> 57052 | D14: =SUM(D10:D13) -> 150 | E14: =SUM(E10:E13) -> 1 | G14: Total | H14: =SUM(H10:H13) -> 57052 | I14: =SUM(I10:I13) -> 150 | J14: =SUM(J10:J13) -> 1
B16: Revenue by Channel | G16: Revenue by Customer Segment
B17: Channel | C17: Revenue | D17: Orders | E17: Share | G17: Segment | H17: Revenue | I17: Orders | J17: Share
B18: Online | C18: =SUMIFS(Retail_Data!$K$2:$K$151,Retail_Data!$F$2:$F$151,$B18) -> 21792.5 | D18: =COUNTIFS(Retail_Data!$F$2:$F$151,$B18) -> 65 | E18: =C18/$B$6 -> 0.38197609 | G18: New | H18: =SUMIFS(Retail_Data!$K$2:$K$151,Retail_Data!$G$2:$G$151,$G18) -> 29128.75 | I18: =COUNTIFS(Retail_Data!$G$2:$G$151,$G18) -> 60 | J18: =H18/$B$6 -> 0.51056492
B19: Offline | C19: =SUMIFS(Retail_Data!$K$2:$K$151,Retail_Data!$F$2:$F$151,$B19) -> 17771 | D19: =COUNTIFS(Retail_Data!$F$2:$F$151,$B19) -> 43 | E19: =C19/$B$6 -> 0.31148777 | G19: VIP | H19: =SUMIFS(Retail_Data!$K$2:$K$151,Retail_Data!$G$2:$G$151,$G19) -> 17185 | I19: =COUNTIFS(Retail_Data!$G$2:$G$151,$G19) -> 48 | J19: =H19/$B$6 -> 0.30121643
B20: Omnichannel | C20: =SUMIFS(Retail_Data!$K$2:$K$151,Retail_Data!$F$2:$F$151,$B20) -> 17488.5 | D20: =COUNTIFS(Retail_Data!$F$2:$F$151,$B20) -> 42 | E20: =C20/$B$6 -> 0.30653614 | G20: Returning | H20: =SUMIFS(Retail_Data!$K$2:$K$151,Retail_Data!$G$2:$G$151,$G20) -> 10738.25 | I20: =COUNTIFS(Retail_Data!$G$2:$G$151,$G20) -> 42 | J20: =H20/$B$6 -> 0.18821864
B21: Total | C21: =SUM(C18:C20) -> 57052 | D21: =SUM(D18:D20) -> 150 | E21: =SUM(E18:E20) -> 1 | G21: Total | H21: =SUM(H18:H20) -> 57052 | I21: =SUM(I18:I20) -> 150 | J21: =SUM(J18:J20) -> 1
B23: Monthly Revenue Trend | G23: Product Ranking
B24: Month | C24: Revenue | D24: Orders | E24: Avg Order | G24: Product | H24: Revenue | I24: Units | J24: Rank
B25: 46023 | C25: =SUMIFS(Retail_Data!$K$2:$K$151,Retail_Data!$B$2:$B$151,">="&$B25,Retail_Data!$B$2:$B$151,"<="&EOMONTH($B25,0)) -> 11372 | D25: =COUNTIFS(Retail_Data!$B$2:$B$151,">="&$B25,Retail_Data!$B$2:$B$151,"<="&EOMONTH($B25,0)) -> 26 | E25: =IFERROR(C25/D25,0) -> 437.38462 | G25: Laptop | H25: =SUMIFS(Retail_Data!$K$2:$K$151,Retail_Data!$C$2:$C$151,$G25) -> 17192.5 | I25: =SUMIFS(Retail_Data!$H$2:$H$151,Retail_Data!$C$2:$C$151,$G25) -> 30 | J25: =RANK(H25,$H$25:$H$36) -> 1
B26: 46054 | C26: =SUMIFS(Retail_Data!$K$2:$K$151,Retail_Data!$B$2:$B$151,">="&$B26,Retail_Data!$B$2:$B$151,"<="&EOMONTH($B26,0)) -> 12513 | D26: =COUNTIFS(Retail_Data!$B$2:$B$151,">="&$B26,Retail_Data!$B$2:$B$151,"<="&EOMONTH($B26,0)) -> 23 | E26: =IFERROR(C26/D26,0) -> 544.04348 | G26: Dining Table | H26: =SUMIFS(Retail_Data!$K$2:$K$151,Retail_Data!$C$2:$C$151,$G26) -> 7798 | I26: =SUMIFS(Retail_Data!$H$2:$H$151,Retail_Data!$C$2:$C$151,$G26) -> 30 | J26: =RANK(H26,$H$25:$H$36) -> 2
B27: 46082 | C27: =SUMIFS(Retail_Data!$K$2:$K$151,Retail_Data!$B$2:$B$151,">="&$B27,Retail_Data!$B$2:$B$151,"<="&EOMONTH($B27,0)) -> 6254.25 | D27: =COUNTIFS(Retail_Data!$B$2:$B$151,">="&$B27,Retail_Data!$B$2:$B$151,"<="&EOMONTH($B27,0)) -> 26 | E27: =IFERROR(C27/D27,0) -> 240.54808 | G27: Smartphone | H27: =SUMIFS(Retail_Data!$K$2:$K$151,Retail_Data!$C$2:$C$151,$G27) -> 7035 | I27: =SUMIFS(Retail_Data!$H$2:$H$151,Retail_Data!$C$2:$C$151,$G27) -> 19 | J27: =RANK(H27,$H$25:$H$36) -> 3
B28: 46113 | C28: =SUMIFS(Retail_Data!$K$2:$K$151,Retail_Data!$B$2:$B$151,">="&$B28,Retail_Data!$B$2:$B$151,"<="&EOMONTH($B28,0)) -> 8361 | D28: =COUNTIFS(Retail_Data!$B$2:$B$151,">="&$B28,Retail_Data!$B$2:$B$151,"<="&EOMONTH($B28,0)) -> 25 | E28: =IFERROR(C28/D28,0) -> 334.44 | G28: Baby Stroller | H28: =SUMIFS(Retail_Data!$K$2:$K$151,Retail_Data!$C$2:$C$151,$G28) -> 6516 | I28: =SUMIFS(Retail_Data!$H$2:$H$151,Retail_Data!$C$2:$C$151,$G28) -> 40 | J28: =RANK(H28,$H$25:$H$36) -> 4
B29: 46143 | C29: =SUMIFS(Retail_Data!$K$2:$K$151,Retail_Data!$B$2:$B$151,">="&$B29,Retail_Data!$B$2:$B$151,"<="&EOMONTH($B29,0)) -> 12349.75 | D29: =COUNTIFS(Retail_Data!$B$2:$B$151,">="&$B29,Retail_Data!$B$2:$B$151,"<="&EOMONTH($B29,0)) -> 25 | E29: =IFERROR(C29/D29,0) -> 493.99 | G29: Sofa | H29: =SUMIFS(Retail_Data!$K$2:$K$151,Retail_Data!$C$2:$C$151,$G29) -> 5145 | I29: =SUMIFS(Retail_Data!$H$2:$H$151,Retail_Data!$C$2:$C$151,$G29) -> 16 | J29: =RANK(H29,$H$25:$H$36) -> 5
B30: 46174 | C30: =SUMIFS(Retail_Data!$K$2:$K$151,Retail_Data!$B$2:$B$151,">="&$B30,Retail_Data!$B$2:$B$151,"<="&EOMONTH($B30,0)) -> 6202 | D30: =COUNTIFS(Retail_Data!$B$2:$B$151,">="&$B30,Retail_Data!$B$2:$B$151,"<="&EOMONTH($B30,0)) -> 25 | E30: =IFERROR(C30/D30,0) -> 248.08 | G30: Sneakers | H30: =SUMIFS(Retail_Data!$K$2:$K$151,Retail_Data!$C$2:$C$151,$G30) -> 3062.5 | I30: =SUMIFS(Retail_Data!$H$2:$H$151,Retail_Data!$C$2:$C$151,$G30) -> 48 | J30: =RANK(H30,$H$25:$H$36) -> 6
G31: Headphones | H31: =SUMIFS(Retail_Data!$K$2:$K$151,Retail_Data!$C$2:$C$151,$G31) -> 2716 | I31: =SUMIFS(Retail_Data!$H$2:$H$151,Retail_Data!$C$2:$C$151,$G31) -> 40 | J31: =RANK(H31,$H$25:$H$36) -> 7
G32: Jeans | H32: =SUMIFS(Retail_Data!$K$2:$K$151,Retail_Data!$C$2:$C$151,$G32) -> 2448 | I32: =SUMIFS(Retail_Data!$H$2:$H$151,Retail_Data!$C$2:$C$151,$G32) -> 59 | J32: =RANK(H32,$H$25:$H$36) -> 8
G33: Cookware Set | H33: =SUMIFS(Retail_Data!$K$2:$K$151,Retail_Data!$C$2:$C$151,$G33) -> 1800.25 | I33: =SUMIFS(Retail_Data!$H$2:$H$151,Retail_Data!$C$2:$C$151,$G33) -> 21 | J33: =RANK(H33,$H$25:$H$36) -> 9
G34: Baby Shoes | H34: =SUMIFS(Retail_Data!$K$2:$K$151,Retail_Data!$C$2:$C$151,$G34) -> 1278 | I34: =SUMIFS(Retail_Data!$H$2:$H$151,Retail_Data!$C$2:$C$151,$G34) -> 48 | J34: =RANK(H34,$H$25:$H$36) -> 10
G35: Diapers | H35: =SUMIFS(Retail_Data!$K$2:$K$151,Retail_Data!$C$2:$C$151,$G35) -> 1083.25 | I35: =SUMIFS(Retail_Data!$H$2:$H$151,Retail_Data!$C$2:$C$151,$G35) -> 35 | J35: =RANK(H35,$H$25:$H$36) -> 11
G36: T-Shirt | H36: =SUMIFS(Retail_Data!$K$2:$K$151,Retail_Data!$C$2:$C$151,$G36) -> 977.5 | I36: =SUMIFS(Retail_Data!$H$2:$H$151,Retail_Data!$C$2:$C$151,$G36) -> 42 | J36: =RANK(H36,$H$25:$H$36) -> 12

Sheet Retail_Data
A1: Order_ID | B1: Order_Date | C1: Product | D1: Category | E1: Region | F1: Channel | G1: Customer_Segment | H1: Units | I1: Unit_Price | J1: Discount_Pct | K1: Revenue | L1: Payment_Method
A2: 1001 | B2: 46023 | C2: Sofa | D2: Home | E2: East | F2: Omnichannel | G2: New | H2: 4 | I2: 350 | J2: 0.2 | K2: =H2*I2*(1-J2) -> 1120 | L2: Credit Card
A3: 1002 | B3: 46024 | C3: Sofa | D3: Home | E3: East | F3: Omnichannel | G3: VIP | H3: 2 | I3: 350 | J3: 0.1 | K3: =H3*I3*(1-J3) -> 630 | L3: Cash
A4: 1003 | B4: 46025 | C4: Jeans | D4: Fashion | E4: South | F4: Online | G4: Returning | H4: 4 | I4: 45 | J4: 0.1 | K4: =H4*I4*(1-J4) -> 162 | L4: Cash
A5: 1004 | B5: 46026 | C5: Baby Shoes | D5: Baby | E5: North | F5: Online | G5: Returning | H5: 2 | I5: 30 | J5: 0.15 | K5: =H5*I5*(1-J5) -> 51 | L5: Debit Card
A6: 1005 | B6: 46027 | C6: Baby Shoes | D6: Baby | E6: East | F6: Omnichannel | G6: VIP | H6: 1 | I6: 30 | J6: 0 | K6: =H6*I6*(1-J6) -> 30 | L6: Debit Card
A7: 1006 | B7: 46029 | C7: Baby Shoes | D7: Baby | E7: West | F7: Omnichannel | G7: New | H7: 4 | I7: 30 | J7: 0.1 | K7: =H7*I7*(1-J7) -> 108 | L7: UPI
A8: 1007 | B8: 46030 | C8: Jeans | D8: Fashion | E8: North | F8: Omnichannel | G8: Returning | H8: 3 | I8: 45 | J8: 0.2 | K8: =H8*I8*(1-J8) -> 108 | L8: Cash
A9: 1008 | B9: 46031 | C9: Cookware Set | D9: Home | E9: South | F9: Online | G9: Returning | H9: 4 | I9: 95 | J9: 0.05 | K9: =H9*I9*(1-J9) -> 361 | L9: Credit Card
A10: 1009 | B10: 46032 | C10: Smartphone | D10: Electronics | E10: East | F10: Omnichannel | G10: New | H10: 4 | I10: 420 | J10: 0.15 | K10: =H10*I10*(1-J10) -> 1428 | L10: Cash
A11: 1010 | B11: 46033 | C11: Headphones | D11: Electronics | E11: South | F11: Offline | G11: Returning | H11: 1 | I11: 80 | J11: 0.15 | K11: =H11*I11*(1-J11) -> 68 | L11: Debit Card
A12: 1011 | B12: 46035 | C12: Sneakers | D12: Fashion | E12: South | F12: Online | G12: VIP | H12: 2 | I12: 70 | J12: 0.15 | K12: =H12*I12*(1-J12) -> 119 | L12: Debit Card
A13: 1012 | B13: 46036 | C13: Baby Stroller | D13: Baby | E13: South | F13: Offline | G13: Returning | H13: 4 | I13: 180 | J13: 0.05 | K13: =H13*I13*(1-J13) -> 684 | L13: UPI
... A151: 1150 | B151: 46203 | C151: Sneakers | D151: Fashion | E151: West | F151: Online | G151: New | H151: 4 | I151: 70 | J151: 0.1 | K151: =H151*I151*(1-J151) -> 252 | L151: Cash

Sheet Cell_References
A1: Relative, Absolute & Mixed Cell References
A2: How $ signs control what changes when a formula is copied — the foundation of every reusable report.
A3: Excel skills: Relative (A1), absolute ($A$1), mixed ($A1 / A$1) references
A4: ■ Navy header = raw data ■ Green header = calculated with formulas
A6: 1. Relative + absolute: GST on product sales
A7: GST rate (input): | C7: 0.18 | D7: ← change this one cell and every GST amount updates (=D9*$C$7)
A8: Product | B8: Units Sold | C8: Price / Unit | D8: Sales Amount | E8: GST Amount | F8: Final Amount
A9: Laptop | B9: 2 | C9: 50000 | D9: =B9*C9 -> 100000 | E9: =D9*$C$7 -> 18000 | F9: =D9+E9 -> 118000
A10: Mobile | B10: 5 | C10: 20000 | D10: =B10*C10 -> 100000 | E10: =D10*$C$7 -> 18000 | F10: =D10+E10 -> 118000
A11: TV | B11: 3 | C11: 35000 | D11: =B11*C11 -> 105000 | E11: =D11*$C$7 -> 18900 | F11: =D11+E11 -> 123900
A12: Refrigerator | B12: 1 | C12: 45000 | D12: =B12*C12 -> 45000 | E12: =D12*$C$7 -> 8100 | F12: =D12+E12 -> 53100
A13: Washing Machine | B13: 2 | C13: 30000 | D13: =B13*C13 -> 60000 | E13: =D13*$C$7 -> 10800 | F13: =D13+E13 -> 70800
A14: Tablet | B14: 4 | C14: 15000 | D14: =B14*C14 -> 60000 | E14: =D14*$C$7 -> 10800 | F14: =D14+E14 -> 70800
A15: Speaker | B15: 6 | C15: 5000 | D15: =B15*C15 -> 30000 | E15: =D15*$C$7 -> 5400 | F15: =D15+E15 -> 35400
A16: AC | B16: 2 | C16: 40000 | D16: =B16*C16 -> 80000 | E16: =D16*$C$7 -> 14400 | F16: =D16+E16 -> 94400
A17: Total | B17: =SUM(B9:B16) -> 25 | D17: =SUM(D9:D16) -> 580000 | E17: =SUM(E9:E16) -> 104400 | F17: =SUM(F9:F16) -> 684400
A20: 2. Mixed reference — column fixed ($B): did each employee beat their own target?
A21: Employee | B21: Target | C21: Jan | D21: Feb | E21: Mar | F21: Jan Met? | G21: Feb Met? | H21: Mar Met?
A22: Ravi | B22: 90 | C22: 95 | D22: 92 | E22: 88 | F22: =C22>$B22 -> TRUE | G22: =D22>$B22 -> TRUE | H22: =E22>$B22 -> FALSE
A23: Priya | B23: 85 | C23: 80 | D23: 90 | E23: 91 | F23: =C23>$B23 -> FALSE | G23: =D23>$B23 -> TRUE | H23: =E23>$B23 -> TRUE
A24: Arjun | B24: 95 | C24: 96 | D24: 94 | E24: 97 | F24: =C24>$B24 -> TRUE | G24: =D24>$B24 -> FALSE | H24: =E24>$B24 -> TRUE
A25: Formula in F22: =C22>$B22 → copied right, the month column moves but the Target column ($B) stays locked.
A28: 3. Mixed reference — row fixed (row 30): monthly tax with a different rate each month
A29: Product | B29: Jan | C29: Feb | D29: Mar | E29: Apr | G29: Tax Jan | H29: Tax Feb | I29: Tax Mar | J29: Tax Apr
A30: Tax Rate | B30: 0.05 | C30: 0.08 | D30: 0.1 | E30: 0.12
A31: Product A | B31: 10000 | C31: 12000 | D31: 15000 | E31: 18000 | G31: =B31*B$30 -> 500 | H31: =C31*C$30 -> 960 | I31: =D31*D$30 -> 1500 | J31: =E31*E$30 -> 2160
A32: Product B | B32: 20000 | C32: 22000 | D32: 25000 | E32: 28000 | G32: =B32*B$30 -> 1000 | H32: =C32*C$30 -> 1760 | I32: =D32*D$30 -> 2500 | J32: =E32*E$30 -> 3360
A33: Product C | B33: 15000 | C33: 18000 | D33: 20000 | E33: 24000 | G33: =B33*B$30 -> 750 | H33: =C33*C$30 -> 1440 | I33: =D33*D$30 -> 2000 | J33: =E33*E$30 -> 2880
A34: Formula in G31: =B31*B$30 → copied down, the product row moves but the Tax Rate row (30) stays locked.

Sheet IF_Logic
A1: IF, AND & OR — Business Rules on Sales Invoices
A2: 20 manager requests turned into formula columns: flags for VIP customers, bulk orders, fraud checks, tax and data quality.
A3: Excel skills: IF, IF + AND, IF + OR, nested IF, IF with calculations, blank checks
A4: ■ Navy header = raw data ■ Green header = calculated with formulas
A6: Invoice No | B6: Customer | C6: Category | D6: Sales Amount | E6: Units Sold | F6: Discount % | G6: Payment Mode | H6: Returns | I6: Membership | J6: Sales Remark | K6: Premium Customer | L6: Bulk Purchase | M6: Discount Status | N6: Return Alert | O6: Loyalty Check | P6: Offer Eligibility | Q6: Bonus Revenue | R6: Category Type | S6: Payment Remark | T6: Customer Grade | U6: Sales Tax | V6: EMI Check | W6: Stock Movement | X6: Fraud Check | Y6: Festival Discount | Z6: Refund Risk | AA6: Invoice Status | AB6: Data Validation | AC6: Business Insight
A7: INV001 | B7: Bhumika | C7: Electronics | D7: 18500 | E7: 2 | F7: 0.1 | G7: Card | H7: 0 | I7: Gold | J7: =IF(D7>=10000,"High Sales","Low Sales") -> High Sales | K7: =IF(I7="Gold","VIP","Normal") -> VIP | L7: =IF(E7>=10,"Bulk Order","Normal Order") -> Normal Order | M7: =IF(F7>=15%,"Heavy Discount","Normal Discount") -> Normal Discount | N7: =IF(H7>0,"Attention Needed","No Return") -> No Return | O7: =IF(AND(D7>=10000,I7="Gold"),"Loyal","Not Loyal") -> Loyal | P7: =IF(OR(D7>=15000,E7>=10),"Eligible","Not Eligible") -> Eligible | Q7: =IF(D7>=20000,D7+500,D7) -> 18500 | R7: =IF(C7="Electronics","Tech Product","Non-Tech") -> Tech Product | S7: =IF(G7="UPI","Digital Payment","Other Payment") -> Other Payment | T7: =IF(D7>=20000,"A",IF(D7>=10000,"B",IF(D7>=5000,"C","D"))) -> B | U7: =IF(C7="Electronics",D7*18%,D7*5%) -> 3330 | V7: =IF(G7="EMI","EMI Purchase","Normal Purchase") -> Normal Purchase | W7: =IF(E7>8,"Fast Moving","Slow Moving") -> Slow Moving | X7: =IF(AND(D7>20000,G7="Cash"),"Verify Transaction","OK") -> OK | Y7: =IF(I7="Platinum",F7+5%,F7) -> 0.1 | Z7: =IF(H7>=2,"High Risk","Low Risk") -> Low Risk | AA7: =IF(D7>=15000,"Large Bill","Regular Bill") -> Large Bill | AB7: =IF(D7="","Missing Data","Complete") -> Complete | AC7: =IF(AND(D7>=10000,H7=0),"Top Customer","Regular") -> Top Customer
A8: INV002 | B8: Bhavana | C8: Fashion | D8: 4200 | E8: 5 | F8: 0.05 | G8: Cash | H8: 1 | I8: Silver | J8: =IF(D8>=10000,"High Sales","Low Sales") -> Low Sales | K8: =IF(I8="Gold","VIP","Normal") -> Normal | L8: =IF(E8>=10,"Bulk Order","Normal Order") -> Normal Order | M8: =IF(F8>=15%,"Heavy Discount","Normal Discount") -> Normal Discount | N8: =IF(H8>0,"Attention Needed","No Return") -> Attention Needed | O8: =IF(AND(D8>=10000,I8="Gold"),"Loyal","Not Loyal") -> Not Loyal | P8: =IF(OR(D8>=15000,E8>=10),"Eligible","Not Eligible") -> Not Eligible | Q8: =IF(D8>=20000,D8+500,D8) -> 4200 | R8: =IF(C8="Electronics","Tech Product","Non-Tech") -> Non-Tech | S8: =IF(G8="UPI","Digital Payment","Other Payment") -> Other Payment | T8: =IF(D8>=20000,"A",IF(D8>=10000,"B",IF(D8>=5000,"C","D"))) -> D | U8: =IF(C8="Electronics",D8*18%,D8*5%) -> 210 | V8: =IF(G8="EMI","EMI Purchase","Normal Purchase") -> Normal Purchase | W8: =IF(E8>8,"Fast Moving","Slow Moving") -> Slow Moving | X8: =IF(AND(D8>20000,G8="Cash"),"Verify Transaction","OK") -> OK | Y8: =IF(I8="Platinum",F8+5%,F8) -> 0.05 | Z8: =IF(H8>=2,"High Risk","Low Risk") -> Low Risk | AA8: =IF(D8>=15000,"Large Bill","Regular Bill") -> Regular Bill | AB8: =IF(D8="","Missing Data","Complete") -> Complete | AC8: =IF(AND(D8>=10000,H8=0),"Top Customer","Regular") -> Regular
A9: INV003 | B9: Charmi | C9: Grocery | D9: 1500 | E9: 12 | F9: 0.02 | G9: UPI | H9: 0 | I9: Regular | J9: =IF(D9>=10000,"High Sales","Low Sales") -> Low Sales | K9: =IF(I9="Gold","VIP","Normal") -> Normal | L9: =IF(E9>=10,"Bulk Order","Normal Order") -> Bulk Order | M9: =IF(F9>=15%,"Heavy Discount","Normal Discount") -> Normal Discount | N9: =IF(H9>0,"Attention Needed","No Return") -> No Return | O9: =IF(AND(D9>=10000,I9="Gold"),"Loyal","Not Loyal") -> Not Loyal | P9: =IF(OR(D9>=15000,E9>=10),"Eligible","Not Eligible") -> Eligible | Q9: =IF(D9>=20000,D9+500,D9) -> 1500 | R9: =IF(C9="Electronics","Tech Product","Non-Tech") -> Non-Tech | S9: =IF(G9="UPI","Digital Payment","Other Payment") -> Digital Payment | T9: =IF(D9>=20000,"A",IF(D9>=10000,"B",IF(D9>=5000,"C","D"))) -> D | U9: =IF(C9="Electronics",D9*18%,D9*5%) -> 75 | V9: =IF(G9="EMI","EMI Purchase","Normal Purchase") -> Normal Purchase | W9: =IF(E9>8,"Fast Moving","Slow Moving") -> Fast Moving | X9: =IF(AND(D9>20000,G9="Cash"),"Verify Transaction","OK") -> OK | Y9: =IF(I9="Platinum",F9+5%,F9) -> 0.02 | Z9: =IF(H9>=2,"High Risk","Low Risk") -> Low Risk | AA9: =IF(D9>=15000,"Large Bill","Regular Bill") -> Regular Bill | AB9: =IF(D9="","Missing Data","Complete") -> Complete | AC9: =IF(AND(D9>=10000,H9=0),"Top Customer","Regular") -> Regular
A10: INV004 | B10: Deepak | C10: Home Decor | D10: 9200 | E10: 7 | F10: 0.15 | G10: Card | H10: 0 | I10: Gold | J10: =IF(D10>=10000,"High Sales","Low Sales") -> Low Sales | K10: =IF(I10="Gold","VIP","Normal") -> VIP | L10: =IF(E10>=10,"Bulk Order","Normal Order") -> Normal Order | M10: =IF(F10>=15%,"Heavy Discount","Normal Discount") -> Heavy Discount | N10: =IF(H10>0,"Attention Needed","No Return") -> No Return | O10: =IF(AND(D10>=10000,I10="Gold"),"Loyal","Not Loyal") -> Not Loyal | P10: =IF(OR(D10>=15000,E10>=10),"Eligible","Not Eligible") -> Not Eligible | Q10: =IF(D10>=20000,D10+500,D10) -> 9200 | R10: =IF(C10="Electronics","Tech Product","Non-Tech") -> Non-Tech | S10: =IF(G10="UPI","Digital Payment","Other Payment") -> Other Payment | T10: =IF(D10>=20000,"A",IF(D10>=10000,"B",IF(D10>=5000,"C","D"))) -> C | U10: =IF(C10="Electronics",D10*18%,D10*5%) -> 460 | V10: =IF(G10="EMI","EMI Purchase","Normal Purchase") -> Normal Purchase | W10: =IF(E10>8,"Fast Moving","Slow Moving") -> Slow Moving | X10: =IF(AND(D10>20000,G10="Cash"),"Verify Transaction","OK") -> OK | Y10: =IF(I10="Platinum",F10+5%,F10) -> 0.15 | Z10: =IF(H10>=2,"High Risk","Low Risk") -> Low Risk | AA10: =IF(D10>=15000,"Large Bill","Regular Bill") -> Regular Bill | AB10: =IF(D10="","Missing Data","Complete") -> Complete | AC10: =IF(AND(D10>=10000,H10=0),"Top Customer","Regular") -> Regular
A11: INV005 | B11: Deepak | C11: Electronics | D11: 25000 | E11: 3 | F11: 0.2 | G11: EMI | H11: 0 | I11: Platinum | J11: =IF(D11>=10000,"High Sales","Low Sales") -> High Sales | K11: =IF(I11="Gold","VIP","Normal") -> Normal | L11: =IF(E11>=10,"Bulk Order","Normal Order") -> Normal Order | M11: =IF(F11>=15%,"Heavy Discount","Normal Discount") -> Heavy Discount | N11: =IF(H11>0,"Attention Needed","No Return") -> No Return | O11: =IF(AND(D11>=10000,I11="Gold"),"Loyal","Not Loyal") -> Not Loyal | P11: =IF(OR(D11>=15000,E11>=10),"Eligible","Not Eligible") -> Eligible | Q11: =IF(D11>=20000,D11+500,D11) -> 25500 | R11: =IF(C11="Electronics","Tech Product","Non-Tech") -> Tech Product | S11: =IF(G11="UPI","Digital Payment","Other Payment") -> Other Payment | T11: =IF(D11>=20000,"A",IF(D11>=10000,"B",IF(D11>=5000,"C","D"))) -> A | U11: =IF(C11="Electronics",D11*18%,D11*5%) -> 4500 | V11: =IF(G11="EMI","EMI Purchase","Normal Purchase") -> EMI Purchase | W11: =IF(E11>8,"Fast Moving","Slow Moving") -> Slow Moving | X11: =IF(AND(D11>20000,G11="Cash"),"Verify Transaction","OK") -> OK | Y11: =IF(I11="Platinum",F11+5%,F11) -> 0.25 | Z11: =IF(H11>=2,"High Risk","Low Risk") -> Low Risk | AA11: =IF(D11>=15000,"Large Bill","Regular Bill") -> Large Bill | AB11: =IF(D11="","Missing Data","Complete") -> Complete | AC11: =IF(AND(D11>=10000,H11=0),"Top Customer","Regular") -> Top Customer
A12: INV006 | B12: Harika | C12: Grocery | D12: 1800 | E12: 10 | F12: 0 | G12: Cash | H12: 2 | I12: Regular | J12: =IF(D12>=10000,"High Sales","Low Sales") -> Low Sales | K12: =IF(I12="Gold","VIP","Normal") -> Normal | L12: =IF(E12>=10,"Bulk Order","Normal Order") -> Bulk Order | M12: =IF(F12>=15%,"Heavy Discount","Normal Discount") -> Normal Discount | N12: =IF(H12>0,"Attention Needed","No Return") -> Attention Needed | O12: =IF(AND(D12>=10000,I12="Gold"),"Loyal","Not Loyal") -> Not Loyal | P12: =IF(OR(D12>=15000,E12>=10),"Eligible","Not Eligible") -> Eligible | Q12: =IF(D12>=20000,D12+500,D12) -> 1800 | R12: =IF(C12="Electronics","Tech Product","Non-Tech") -> Non-Tech | S12: =IF(G12="UPI","Digital Payment","Other Payment") -> Other Payment | T12: =IF(D12>=20000,"A",IF(D12>=10000,"B",IF(D12>=5000,"C","D"))) -> D | U12: =IF(C12="Electronics",D12*18%,D12*5%) -> 90 | V12: =IF(G12="EMI","EMI Purchase","Normal Purchase") -> Normal Purchase | W12: =IF(E12>8,"Fast Moving","Slow Moving") -> Fast Moving | X12: =IF(AND(D12>20000,G12="Cash"),"Verify Transaction","OK") -> OK | Y12: =IF(I12="Platinum",F12+5%,F12) -> 0 | Z12: =IF(H12>=2,"High Risk","Low Risk") -> High Risk | AA12: =IF(D12>=15000,"Large Bill","Regular Bill") -> Regular Bill | AB12: =IF(D12="","Missing Data","Complete") -> Complete | AC12: =IF(AND(D12>=10000,H12=0),"Top Customer","Regular") -> Regular
A13: INV007 | B13: Jignash | C13: Fashion | D13: 12500 | E13: 9 | F13: 0.12 | G13: Card | H13: 0 | I13: Gold | J13: =IF(D13>=10000,"High Sales","Low Sales") -> High Sales | K13: =IF(I13="Gold","VIP","Normal") -> VIP | L13: =IF(E13>=10,"Bulk Order","Normal Order") -> Normal Order | M13: =IF(F13>=15%,"Heavy Discount","Normal Discount") -> Normal Discount | N13: =IF(H13>0,"Attention Needed","No Return") -> No Return | O13: =IF(AND(D13>=10000,I13="Gold"),"Loyal","Not Loyal") -> Loyal | P13: =IF(OR(D13>=15000,E13>=10),"Eligible","Not Eligible") -> Not Eligible | Q13: =IF(D13>=20000,D13+500,D13) -> 12500 | R13: =IF(C13="Electronics","Tech Product","Non-Tech") -> Non-Tech | S13: =IF(G13="UPI","Digital Payment","Other Payment") -> Other Payment | T13: =IF(D13>=20000,"A",IF(D13>=10000,"B",IF(D13>=5000,"C","D"))) -> B | U13: =IF(C13="Electronics",D13*18%,D13*5%) -> 625 | V13: =IF(G13="EMI","EMI Purchase","Normal Purchase") -> Normal Purchase | W13: =IF(E13>8,"Fast Moving","Slow Moving") -> Fast Moving | X13: =IF(AND(D13>20000,G13="Cash"),"Verify Transaction","OK") -> OK | Y13: =IF(I13="Platinum",F13+5%,F13) -> 0.12 | Z13: =IF(H13>=2,"High Risk","Low Risk") -> Low Risk | AA13: =IF(D13>=15000,"Large Bill","Regular Bill") -> Regular Bill | AB13: =IF(D13="","Missing Data","Complete") -> Complete | AC13: =IF(AND(D13>=10000,H13=0),"Top Customer","Regular") -> Top Customer
A14: INV008 | B14: Sowmya | C14: Electronics | D14: 8000 | E14: 1 | F14: 0.05 | G14: UPI | H14: 0 | I14: Silver | J14: =IF(D14>=10000,"High Sales","Low Sales") -> Low Sales | K14: =IF(I14="Gold","VIP","Normal") -> Normal | L14: =IF(E14>=10,"Bulk Order","Normal Order") -> Normal Order | M14: =IF(F14>=15%,"Heavy Discount","Normal Discount") -> Normal Discount | N14: =IF(H14>0,"Attention Needed","No Return") -> No Return | O14: =IF(AND(D14>=10000,I14="Gold"),"Loyal","Not Loyal") -> Not Loyal | P14: =IF(OR(D14>=15000,E14>=10),"Eligible","Not Eligible") -> Not Eligible | Q14: =IF(D14>=20000,D14+500,D14) -> 8000 | R14: =IF(C14="Electronics","Tech Product","Non-Tech") -> Tech Product | S14: =IF(G14="UPI","Digital Payment","Other Payment") -> Digital Payment | T14: =IF(D14>=20000,"A",IF(D14>=10000,"B",IF(D14>=5000,"C","D"))) -> C | U14: =IF(C14="Electronics",D14*18%,D14*5%) -> 1440 | V14: =IF(G14="EMI","EMI Purchase","Normal Purchase") -> Normal Purchase | W14: =IF(E14>8,"Fast Moving","Slow Moving") -> Slow Moving | X14: =IF(AND(D14>20000,G14="Cash"),"Verify Transaction","OK") -> OK | Y14: =IF(I14="Platinum",F14+5%,F14) -> 0.05 | Z14: =IF(H14>=2,"High Risk","Low Risk") -> Low Risk | AA14: =IF(D14>=15000,"Large Bill","Regular Bill") -> Regular Bill | AB14: =IF(D14="","Missing Data","Complete") -> Complete | AC14: =IF(AND(D14>=10000,H14=0),"Top Customer","Regular") -> Regular
A15: INV009 | B15: Reshma | C15: Home Decor | D15: 6700 | E15: 6 | F15: 0.08 | G15: Cash | H15: 1 | I15: Regular | J15: =IF(D15>=10000,"High Sales","Low Sales") -> Low Sales | K15: =IF(I15="Gold","VIP","Normal") -> Normal | L15: =IF(E15>=10,"Bulk Order","Normal Order") -> Normal Order | M15: =IF(F15>=15%,"Heavy Discount","Normal Discount") -> Normal Discount | N15: =IF(H15>0,"Attention Needed","No Return") -> Attention Needed | O15: =IF(AND(D15>=10000,I15="Gold"),"Loyal","Not Loyal") -> Not Loyal | P15: =IF(OR(D15>=15000,E15>=10),"Eligible","Not Eligible") -> Not Eligible | Q15: =IF(D15>=20000,D15+500,D15) -> 6700 | R15: =IF(C15="Electronics","Tech Product","Non-Tech") -> Non-Tech | S15: =IF(G15="UPI","Digital Payment","Other Payment") -> Other Payment | T15: =IF(D15>=20000,"A",IF(D15>=10000,"B",IF(D15>=5000,"C","D"))) -> C | U15: =IF(C15="Electronics",D15*18%,D15*5%) -> 335 | V15: =IF(G15="EMI","EMI Purchase","Normal Purchase") -> Normal Purchase | W15: =IF(E15>8,"Fast Moving","Slow Moving") -> Slow Moving | X15: =IF(AND(D15>20000,G15="Cash"),"Verify Transaction","OK") -> OK | Y15: =IF(I15="Platinum",F15+5%,F15) -> 0.08 | Z15: =IF(H15>=2,"High Risk","Low Risk") -> Low Risk | AA15: =IF(D15>=15000,"Large Bill","Regular Bill") -> Regular Bill | AB15: =IF(D15="","Missing Data","Complete") -> Complete | AC15: =IF(AND(D15>=10000,H15=0),"Top Customer","Regular") -> Regular
A16: INV010 | B16: Keerthi | C16: Grocery | D16: 2300 | E16: 15 | F16: 0 | G16: UPI | H16: 0 | I16: Silver | J16: =IF(D16>=10000,"High Sales","Low Sales") -> Low Sales | K16: =IF(I16="Gold","VIP","Normal") -> Normal | L16: =IF(E16>=10,"Bulk Order","Normal Order") -> Bulk Order | M16: =IF(F16>=15%,"Heavy Discount","Normal Discount") -> Normal Discount | N16: =IF(H16>0,"Attention Needed","No Return") -> No Return | O16: =IF(AND(D16>=10000,I16="Gold"),"Loyal","Not Loyal") -> Not Loyal | P16: =IF(OR(D16>=15000,E16>=10),"Eligible","Not Eligible") -> Eligible | Q16: =IF(D16>=20000,D16+500,D16) -> 2300 | R16: =IF(C16="Electronics","Tech Product","Non-Tech") -> Non-Tech | S16: =IF(G16="UPI","Digital Payment","Other Payment") -> Digital Payment | T16: =IF(D16>=20000,"A",IF(D16>=10000,"B",IF(D16>=5000,"C","D"))) -> D | U16: =IF(C16="Electronics",D16*18%,D16*5%) -> 115 | V16: =IF(G16="EMI","EMI Purchase","Normal Purchase") -> Normal Purchase | W16: =IF(E16>8,"Fast Moving","Slow Moving") -> Fast Moving | X16: =IF(AND(D16>20000,G16="Cash"),"Verify Transaction","OK") -> OK | Y16: =IF(I16="Platinum",F16+5%,F16) -> 0 | Z16: =IF(H16>=2,"High Risk","Low Risk") -> Low Risk | AA16: =IF(D16>=15000,"Large Bill","Regular Bill") -> Regular Bill | AB16: =IF(D16="","Missing Data","Complete") -> Complete | AC16: =IF(AND(D16>=10000,H16=0),"Top Customer","Regular") -> Regular
A19: How each column is calculated
A20: # | B20: Column | C20: Business rule | I20: Formula (first data row)
A21: 1 | B21: Sales Remark | C21: Sales ≥ 10,000 → High Sales, else Low Sales | I21: =IF(D7>=10000,"High Sales","Low Sales")
A22: 2 | B22: Premium Customer | C22: Membership = Gold → VIP, else Normal | I22: =IF(I7="Gold","VIP","Normal")
A23: 3 | B23: Bulk Purchase | C23: Units ≥ 10 → Bulk Order | I23: =IF(E7>=10,"Bulk Order","Normal Order")
A24: 4 | B24: Discount Status | C24: Discount ≥ 15% → Heavy Discount | I24: =IF(F7>=15%,"Heavy Discount","Normal Discount")
A25: 5 | B25: Return Alert | C25: Returns > 0 → Attention Needed | I25: =IF(H7>0,"Attention Needed","No Return")
A26: 6 | B26: Loyalty Check | C26: Sales ≥ 10,000 AND Gold → Loyal | I26: =IF(AND(D7>=10000,I7="Gold"),"Loyal","Not Loyal")
A27: 7 | B27: Offer Eligibility | C27: Sales ≥ 15,000 OR Units ≥ 10 → Eligible | I27: =IF(OR(D7>=15000,E7>=10),"Eligible","Not Eligible")
A28: 8 | B28: Bonus Revenue | C28: Sales ≥ 20,000 → add 500 | I28: =IF(D7>=20000,D7+500,D7)
A29: 9 | B29: Category Type | C29: Electronics → Tech Product, else Non-Tech | I29: =IF(C7="Electronics","Tech Product","Non-Tech")
A30: 10 | B30: Payment Remark | C30: UPI → Digital Payment | I30: =IF(G7="UPI","Digital Payment","Other Payment")
A31: 11 | B31: Customer Grade | C31: A ≥ 20,000 · B ≥ 10,000 · C ≥ 5,000 · else D | I31: =IF(D7>=20000,"A",IF(D7>=10000,"B",IF(D7>=5000,"C","D")))
A32: 12 | B32: Sales Tax | C32: Electronics 18% of sales, others 5% | I32: =IF(C7="Electronics",D7*18%,D7*5%)
... A40: 20 | B40: Business Insight | C40: Sales ≥ 10,000 AND no returns → Top Customer | I40: =IF(AND(D7>=10000,H7=0),"Top Customer","Regular")

Sheet Nested_IF
A1: Nested IF — Customer Segmentation & Management Actions
A2: Multi-level rules (2 to 4 levels) that grade customers, size incentives and decide the next action for the sales team.
A3: Excel skills: Nested IF (up to 4 levels), IF + AND / OR, percentage and calculated outputs
A4: ■ Navy header = raw data ■ Green header = calculated with formulas
A6: Customer | B6: Store Sales | C6: Units | D6: Discount % | E6: Returns | F6: Sales Level | G6: Customer Grade | H6: Sales Category | I6: Units Category | J6: Discount Category | K6: Return Risk | L6: Customer Segment | M6: Performance Rating | N6: Bonus % | O6: Incentive Amount | P6: Purchase Type | Q6: Customer Priority | R6: Discount Action | S6: Return Action | T6: Performance Type | U6: Customer Eligibility | V6: Business Risk | W6: Sales Team Action | X6: Final Customer Status | Y6: Management Action
A7: Sindhuja | B7: 8500 | C7: 12 | D7: 0.1 | E7: 0 | F7: =IF(B7>=15000,"Very High",IF(B7>=10000,"High","Low")) -> Low | G7: =IF(B7>=15000,"A",IF(B7>=10000,"B",IF(B7>=5000,"C","D"))) -> C | H7: =IF(B7>=18000,"Excellent",IF(B7>=15000,"Very Good",IF(B7>=10000,"Good",IF(B7>=5000,"Average","Poor")))) -> Average | I7: =IF(C7>=20,"Bulk",IF(C7>=15,"Large",IF(C7>=10,"Medium","Small"))) -> Medium | J7: =IF(D7>=15%,"Very High Discount",IF(D7>=10%,"High Discount",IF(D7>=5%,"Medium Discount","Low Discount"))) -> High Discount | K7: =IF(E7>=3,"Critical",IF(E7=2,"High",IF(E7=1,"Medium","Low"))) -> Low | L7: =IF(B7>=15000,"Premium",IF(B7>=10000,"Gold",IF(B7>=5000,"Silver","Bronze"))) -> Silver | M7: =IF(B7>=15000,"Excellent",IF(B7>=10000,"Good",IF(B7>=7000,"Average","Needs Improvement"))) -> Average | N7: =IF(B7>=15000,15%,IF(B7>=10000,10%,IF(B7>=5000,5%,0%))) -> 0.05 | O7: =IF(B7>=15000,B7*15%,IF(B7>=10000,B7*10%,IF(B7>=5000,B7*5%,0))) -> 425 | P7: =IF(C7>=20,"Very Large Buyer",IF(C7>=15,"Large Buyer",IF(C7>=10,"Medium Buyer","Small Buyer"))) -> Medium Buyer | Q7: =IF(B7>=15000,"Priority 1",IF(B7>=10000,"Priority 2",IF(B7>=5000,"Priority 3","Priority 4"))) -> Priority 3 | R7: =IF(D7>=15%,"Review Discount",IF(D7>=10%,"Monitor",IF(D7>=5%,"Acceptable","Low Discount"))) -> Monitor | S7: =IF(E7>=3,"Immediate Action",IF(E7=2,"Investigate",IF(E7=1,"Monitor","No Action"))) -> No Action | T7: =IF(AND(B7>=15000,C7>=20),"Top Performer",IF(AND(B7>=10000,C7>=15),"Strong Performer","Regular Performer")) -> Regular Performer | U7: =IF(OR(B7>=15000,C7>=20),"VIP Eligible",IF(OR(B7>=10000,C7>=15),"Eligible","Not Eligible")) -> Not Eligible | V7: =IF(E7>=3,"Critical Risk",IF(AND(E7>=2,B7<8000),"High Risk",IF(E7=1,"Medium Risk","Low Risk"))) -> Low Risk | W7: =IF(B7>=15000,"Reward",IF(B7>=10000,"Appreciate",IF(B7>=5000,"Coach","Train"))) -> Coach | X7: =IF(AND(B7>=15000,E7=0),"Excellent Customer",IF(AND(B7>=10000,E7<=1),"Good Customer",IF(B7>=5000,"Regular Customer","Low Value Customer"))) -> Regular Customer | Y7: =IF(AND(B7>=15000,C7>=20,E7=0),"VIP + Reward",IF(AND(B7>=10000,C7>=15),"Priority Customer",IF(OR(B7>=5000,C7>=10),"Normal Customer","Needs Attention"))) -> Normal Customer
A8: Devika | B8: 4200 | C8: 5 | D8: 0.05 | E8: 1 | F8: =IF(B8>=15000,"Very High",IF(B8>=10000,"High","Low")) -> Low | G8: =IF(B8>=15000,"A",IF(B8>=10000,"B",IF(B8>=5000,"C","D"))) -> D | H8: =IF(B8>=18000,"Excellent",IF(B8>=15000,"Very Good",IF(B8>=10000,"Good",IF(B8>=5000,"Average","Poor")))) -> Poor | I8: =IF(C8>=20,"Bulk",IF(C8>=15,"Large",IF(C8>=10,"Medium","Small"))) -> Small | J8: =IF(D8>=15%,"Very High Discount",IF(D8>=10%,"High Discount",IF(D8>=5%,"Medium Discount","Low Discount"))) -> Medium Discount | K8: =IF(E8>=3,"Critical",IF(E8=2,"High",IF(E8=1,"Medium","Low"))) -> Medium | L8: =IF(B8>=15000,"Premium",IF(B8>=10000,"Gold",IF(B8>=5000,"Silver","Bronze"))) -> Bronze | M8: =IF(B8>=15000,"Excellent",IF(B8>=10000,"Good",IF(B8>=7000,"Average","Needs Improvement"))) -> Needs Improvement | N8: =IF(B8>=15000,15%,IF(B8>=10000,10%,IF(B8>=5000,5%,0%))) -> 0 | O8: =IF(B8>=15000,B8*15%,IF(B8>=10000,B8*10%,IF(B8>=5000,B8*5%,0))) -> 0 | P8: =IF(C8>=20,"Very Large Buyer",IF(C8>=15,"Large Buyer",IF(C8>=10,"Medium Buyer","Small Buyer"))) -> Small Buyer | Q8: =IF(B8>=15000,"Priority 1",IF(B8>=10000,"Priority 2",IF(B8>=5000,"Priority 3","Priority 4"))) -> Priority 4 | R8: =IF(D8>=15%,"Review Discount",IF(D8>=10%,"Monitor",IF(D8>=5%,"Acceptable","Low Discount"))) -> Acceptable | S8: =IF(E8>=3,"Immediate Action",IF(E8=2,"Investigate",IF(E8=1,"Monitor","No Action"))) -> Monitor | T8: =IF(AND(B8>=15000,C8>=20),"Top Performer",IF(AND(B8>=10000,C8>=15),"Strong Performer","Regular Performer")) -> Regular Performer | U8: =IF(OR(B8>=15000,C8>=20),"VIP Eligible",IF(OR(B8>=10000,C8>=15),"Eligible","Not Eligible")) -> Not Eligible | V8: =IF(E8>=3,"Critical Risk",IF(AND(E8>=2,B8<8000),"High Risk",IF(E8=1,"Medium Risk","Low Risk"))) -> Medium Risk | W8: =IF(B8>=15000,"Reward",IF(B8>=10000,"Appreciate",IF(B8>=5000,"Coach","Train"))) -> Train | X8: =IF(AND(B8>=15000,E8=0),"Excellent Customer",IF(AND(B8>=10000,E8<=1),"Good Customer",IF(B8>=5000,"Regular Customer","Low Value Customer"))) -> Low Value Customer | Y8: =IF(AND(B8>=15000,C8>=20,E8=0),"VIP + Reward",IF(AND(B8>=10000,C8>=15),"Priority Customer",IF(OR(B8>=5000,C8>=10),"Normal Customer","Needs Attention"))) -> Needs Attention
A9: Uma | B9: 15000 | C9: 20 | D9: 0.15 | E9: 0 | F9: =IF(B9>=15000,"Very High",IF(B9>=10000,"High","Low")) -> Very High | G9: =IF(B9>=15000,"A",IF(B9>=10000,"B",IF(B9>=5000,"C","D"))) -> A | H9: =IF(B9>=18000,"Excellent",IF(B9>=15000,"Very Good",IF(B9>=10000,"Good",IF(B9>=5000,"Average","Poor")))) -> Very Good | I9: =IF(C9>=20,"Bulk",IF(C9>=15,"Large",IF(C9>=10,"Medium","Small"))) -> Bulk | J9: =IF(D9>=15%,"Very High Discount",IF(D9>=10%,"High Discount",IF(D9>=5%,"Medium Discount","Low Discount"))) -> Very High Discount | K9: =IF(E9>=3,"Critical",IF(E9=2,"High",IF(E9=1,"Medium","Low"))) -> Low | L9: =IF(B9>=15000,"Premium",IF(B9>=10000,"Gold",IF(B9>=5000,"Silver","Bronze"))) -> Premium | M9: =IF(B9>=15000,"Excellent",IF(B9>=10000,"Good",IF(B9>=7000,"Average","Needs Improvement"))) -> Excellent | N9: =IF(B9>=15000,15%,IF(B9>=10000,10%,IF(B9>=5000,5%,0%))) -> 0.15 | O9: =IF(B9>=15000,B9*15%,IF(B9>=10000,B9*10%,IF(B9>=5000,B9*5%,0))) -> 2250 | P9: =IF(C9>=20,"Very Large Buyer",IF(C9>=15,"Large Buyer",IF(C9>=10,"Medium Buyer","Small Buyer"))) -> Very Large Buyer | Q9: =IF(B9>=15000,"Priority 1",IF(B9>=10000,"Priority 2",IF(B9>=5000,"Priority 3","Priority 4"))) -> Priority 1 | R9: =IF(D9>=15%,"Review Discount",IF(D9>=10%,"Monitor",IF(D9>=5%,"Acceptable","Low Discount"))) -> Review Discount | S9: =IF(E9>=3,"Immediate Action",IF(E9=2,"Investigate",IF(E9=1,"Monitor","No Action"))) -> No Action | T9: =IF(AND(B9>=15000,C9>=20),"Top Performer",IF(AND(B9>=10000,C9>=15),"Strong Performer","Regular Performer")) -> Top Performer | U9: =IF(OR(B9>=15000,C9>=20),"VIP Eligible",IF(OR(B9>=10000,C9>=15),"Eligible","Not Eligible")) -> VIP Eligible | V9: =IF(E9>=3,"Critical Risk",IF(AND(E9>=2,B9<8000),"High Risk",IF(E9=1,"Medium Risk","Low Risk"))) -> Low Risk | W9: =IF(B9>=15000,"Reward",IF(B9>=10000,"Appreciate",IF(B9>=5000,"Coach","Train"))) -> Reward | X9: =IF(AND(B9>=15000,E9=0),"Excellent Customer",IF(AND(B9>=10000,E9<=1),"Good Customer",IF(B9>=5000,"Regular Customer","Low Value Customer"))) -> Excellent Customer | Y9: =IF(AND(B9>=15000,C9>=20,E9=0),"VIP + Reward",IF(AND(B9>=10000,C9>=15),"Priority Customer",IF(OR(B9>=5000,C9>=10),"Normal Customer","Needs Attention"))) -> VIP + Reward
A10: Thanuja | B10: 3000 | C10: 4 | D10: 0.02 | E10: 2 | F10: =IF(B10>=15000,"Very High",IF(B10>=10000,"High","Low")) -> Low | G10: =IF(B10>=15000,"A",IF(B10>=10000,"B",IF(B10>=5000,"C","D"))) -> D | H10: =IF(B10>=18000,"Excellent",IF(B10>=15000,"Very Good",IF(B10>=10000,"Good",IF(B10>=5000,"Average","Poor")))) -> Poor | I10: =IF(C10>=20,"Bulk",IF(C10>=15,"Large",IF(C10>=10,"Medium","Small"))) -> Small | J10: =IF(D10>=15%,"Very High Discount",IF(D10>=10%,"High Discount",IF(D10>=5%,"Medium Discount","Low Discount"))) -> Low Discount | K10: =IF(E10>=3,"Critical",IF(E10=2,"High",IF(E10=1,"Medium","Low"))) -> High | L10: =IF(B10>=15000,"Premium",IF(B10>=10000,"Gold",IF(B10>=5000,"Silver","Bronze"))) -> Bronze | M10: =IF(B10>=15000,"Excellent",IF(B10>=10000,"Good",IF(B10>=7000,"Average","Needs Improvement"))) -> Needs Improvement | N10: =IF(B10>=15000,15%,IF(B10>=10000,10%,IF(B10>=5000,5%,0%))) -> 0 | O10: =IF(B10>=15000,B10*15%,IF(B10>=10000,B10*10%,IF(B10>=5000,B10*5%,0))) -> 0 | P10: =IF(C10>=20,"Very Large Buyer",IF(C10>=15,"Large Buyer",IF(C10>=10,"Medium Buyer","Small Buyer"))) -> Small Buyer | Q10: =IF(B10>=15000,"Priority 1",IF(B10>=10000,"Priority 2",IF(B10>=5000,"Priority 3","Priority 4"))) -> Priority 4 | R10: =IF(D10>=15%,"Review Discount",IF(D10>=10%,"Monitor",IF(D10>=5%,"Acceptable","Low Discount"))) -> Low Discount | S10: =IF(E10>=3,"Immediate Action",IF(E10=2,"Investigate",IF(E10=1,"Monitor","No Action"))) -> Investigate | T10: =IF(AND(B10>=15000,C10>=20),"Top Performer",IF(AND(B10>=10000,C10>=15),"Strong Performer","Regular Performer")) -> Regular Performer | U10: =IF(OR(B10>=15000,C10>=20),"VIP Eligible",IF(OR(B10>=10000,C10>=15),"Eligible","Not Eligible")) -> Not Eligible | V10: =IF(E10>=3,"Critical Risk",IF(AND(E10>=2,B10<8000),"High Risk",IF(E10=1,"Medium Risk","Low Risk"))) -> High Risk | W10: =IF(B10>=15000,"Reward",IF(B10>=10000,"Appreciate",IF(B10>=5000,"Coach","Train"))) -> Train | X10: =IF(AND(B10>=15000,E10=0),"Excellent Customer",IF(AND(B10>=10000,E10<=1),"Good Customer",IF(B10>=5000,"Regular Customer","Low Value Customer"))) -> Low Value Customer | Y10: =IF(AND(B10>=15000,C10>=20,E10=0),"VIP + Reward",IF(AND(B10>=10000,C10>=15),"Priority Customer",IF(OR(B10>=5000,C10>=10),"Normal Customer","Needs Attention"))) -> Needs Attention
A11: Alekhya | B11: 9500 | C11: 14 | D11: 0.08 | E11: 0 | F11: =IF(B11>=15000,"Very High",IF(B11>=10000,"High","Low")) -> Low | G11: =IF(B11>=15000,"A",IF(B11>=10000,"B",IF(B11>=5000,"C","D"))) -> C | H11: =IF(B11>=18000,"Excellent",IF(B11>=15000,"Very Good",IF(B11>=10000,"Good",IF(B11>=5000,"Average","Poor")))) -> Average | I11: =IF(C11>=20,"Bulk",IF(C11>=15,"Large",IF(C11>=10,"Medium","Small"))) -> Medium | J11: =IF(D11>=15%,"Very High Discount",IF(D11>=10%,"High Discount",IF(D11>=5%,"Medium Discount","Low Discount"))) -> Medium Discount | K11: =IF(E11>=3,"Critical",IF(E11=2,"High",IF(E11=1,"Medium","Low"))) -> Low | L11: =IF(B11>=15000,"Premium",IF(B11>=10000,"Gold",IF(B11>=5000,"Silver","Bronze"))) -> Silver | M11: =IF(B11>=15000,"Excellent",IF(B11>=10000,"Good",IF(B11>=7000,"Average","Needs Improvement"))) -> Average | N11: =IF(B11>=15000,15%,IF(B11>=10000,10%,IF(B11>=5000,5%,0%))) -> 0.05 | O11: =IF(B11>=15000,B11*15%,IF(B11>=10000,B11*10%,IF(B11>=5000,B11*5%,0))) -> 475 | P11: =IF(C11>=20,"Very Large Buyer",IF(C11>=15,"Large Buyer",IF(C11>=10,"Medium Buyer","Small Buyer"))) -> Medium Buyer | Q11: =IF(B11>=15000,"Priority 1",IF(B11>=10000,"Priority 2",IF(B11>=5000,"Priority 3","Priority 4"))) -> Priority 3 | R11: =IF(D11>=15%,"Review Discount",IF(D11>=10%,"Monitor",IF(D11>=5%,"Acceptable","Low Discount"))) -> Acceptable | S11: =IF(E11>=3,"Immediate Action",IF(E11=2,"Investigate",IF(E11=1,"Monitor","No Action"))) -> No Action | T11: =IF(AND(B11>=15000,C11>=20),"Top Performer",IF(AND(B11>=10000,C11>=15),"Strong Performer","Regular Performer")) -> Regular Performer | U11: =IF(OR(B11>=15000,C11>=20),"VIP Eligible",IF(OR(B11>=10000,C11>=15),"Eligible","Not Eligible")) -> Not Eligible | V11: =IF(E11>=3,"Critical Risk",IF(AND(E11>=2,B11<8000),"High Risk",IF(E11=1,"Medium Risk","Low Risk"))) -> Low Risk | W11: =IF(B11>=15000,"Reward",IF(B11>=10000,"Appreciate",IF(B11>=5000,"Coach","Train"))) -> Coach | X11: =IF(AND(B11>=15000,E11=0),"Excellent Customer",IF(AND(B11>=10000,E11<=1),"Good Customer",IF(B11>=5000,"Regular Customer","Low Value Customer"))) -> Regular Customer | Y11: =IF(AND(B11>=15000,C11>=20,E11=0),"VIP + Reward",IF(AND(B11>=10000,C11>=15),"Priority Customer",IF(OR(B11>=5000,C11>=10),"Normal Customer","Needs Attention"))) -> Normal Customer
A12: Madhuri | B12: 2000 | C12: 3 | D12: 0 | E12: 1 | F12: =IF(B12>=15000,"Very High",IF(B12>=10000,"High","Low")) -> Low | G12: =IF(B12>=15000,"A",IF(B12>=10000,"B",IF(B12>=5000,"C","D"))) -> D | H12: =IF(B12>=18000,"Excellent",IF(B12>=15000,"Very Good",IF(B12>=10000,"Good",IF(B12>=5000,"Average","Poor")))) -> Poor | I12: =IF(C12>=20,"Bulk",IF(C12>=15,"Large",IF(C12>=10,"Medium","Small"))) -> Small | J12: =IF(D12>=15%,"Very High Discount",IF(D12>=10%,"High Discount",IF(D12>=5%,"Medium Discount","Low Discount"))) -> Low Discount | K12: =IF(E12>=3,"Critical",IF(E12=2,"High",IF(E12=1,"Medium","Low"))) -> Medium | L12: =IF(B12>=15000,"Premium",IF(B12>=10000,"Gold",IF(B12>=5000,"Silver","Bronze"))) -> Bronze | M12: =IF(B12>=15000,"Excellent",IF(B12>=10000,"Good",IF(B12>=7000,"Average","Needs Improvement"))) -> Needs Improvement | N12: =IF(B12>=15000,15%,IF(B12>=10000,10%,IF(B12>=5000,5%,0%))) -> 0 | O12: =IF(B12>=15000,B12*15%,IF(B12>=10000,B12*10%,IF(B12>=5000,B12*5%,0))) -> 0 | P12: =IF(C12>=20,"Very Large Buyer",IF(C12>=15,"Large Buyer",IF(C12>=10,"Medium Buyer","Small Buyer"))) -> Small Buyer | Q12: =IF(B12>=15000,"Priority 1",IF(B12>=10000,"Priority 2",IF(B12>=5000,"Priority 3","Priority 4"))) -> Priority 4 | R12: =IF(D12>=15%,"Review Discount",IF(D12>=10%,"Monitor",IF(D12>=5%,"Acceptable","Low Discount"))) -> Low Discount | S12: =IF(E12>=3,"Immediate Action",IF(E12=2,"Investigate",IF(E12=1,"Monitor","No Action"))) -> Monitor | T12: =IF(AND(B12>=15000,C12>=20),"Top Performer",IF(AND(B12>=10000,C12>=15),"Strong Performer","Regular Performer")) -> Regular Performer | U12: =IF(OR(B12>=15000,C12>=20),"VIP Eligible",IF(OR(B12>=10000,C12>=15),"Eligible","Not Eligible")) -> Not Eligible | V12: =IF(E12>=3,"Critical Risk",IF(AND(E12>=2,B12<8000),"High Risk",IF(E12=1,"Medium Risk","Low Risk"))) -> Medium Risk | W12: =IF(B12>=15000,"Reward",IF(B12>=10000,"Appreciate",IF(B12>=5000,"Coach","Train"))) -> Train | X12: =IF(AND(B12>=15000,E12=0),"Excellent Customer",IF(AND(B12>=10000,E12<=1),"Good Customer",IF(B12>=5000,"Regular Customer","Low Value Customer"))) -> Low Value Customer | Y12: =IF(AND(B12>=15000,C12>=20,E12=0),"VIP + Reward",IF(AND(B12>=10000,C12>=15),"Priority Customer",IF(OR(B12>=5000,C12>=10),"Normal Customer","Needs Attention"))) -> Needs Attention
A13: Pavithra | B13: 18000 | C13: 25 | D13: 0.2 | E13: 0 | F13: =IF(B13>=15000,"Very High",IF(B13>=10000,"High","Low")) -> Very High | G13: =IF(B13>=15000,"A",IF(B13>=10000,"B",IF(B13>=5000,"C","D"))) -> A | H13: =IF(B13>=18000,"Excellent",IF(B13>=15000,"Very Good",IF(B13>=10000,"Good",IF(B13>=5000,"Average","Poor")))) -> Excellent | I13: =IF(C13>=20,"Bulk",IF(C13>=15,"Large",IF(C13>=10,"Medium","Small"))) -> Bulk | J13: =IF(D13>=15%,"Very High Discount",IF(D13>=10%,"High Discount",IF(D13>=5%,"Medium Discount","Low Discount"))) -> Very High Discount | K13: =IF(E13>=3,"Critical",IF(E13=2,"High",IF(E13=1,"Medium","Low"))) -> Low | L13: =IF(B13>=15000,"Premium",IF(B13>=10000,"Gold",IF(B13>=5000,"Silver","Bronze"))) -> Premium | M13: =IF(B13>=15000,"Excellent",IF(B13>=10000,"Good",IF(B13>=7000,"Average","Needs Improvement"))) -> Excellent | N13: =IF(B13>=15000,15%,IF(B13>=10000,10%,IF(B13>=5000,5%,0%))) -> 0.15 | O13: =IF(B13>=15000,B13*15%,IF(B13>=10000,B13*10%,IF(B13>=5000,B13*5%,0))) -> 2700 | P13: =IF(C13>=20,"Very Large Buyer",IF(C13>=15,"Large Buyer",IF(C13>=10,"Medium Buyer","Small Buyer"))) -> Very Large Buyer | Q13: =IF(B13>=15000,"Priority 1",IF(B13>=10000,"Priority 2",IF(B13>=5000,"Priority 3","Priority 4"))) -> Priority 1 | R13: =IF(D13>=15%,"Review Discount",IF(D13>=10%,"Monitor",IF(D13>=5%,"Acceptable","Low Discount"))) -> Review Discount | S13: =IF(E13>=3,"Immediate Action",IF(E13=2,"Investigate",IF(E13=1,"Monitor","No Action"))) -> No Action | T13: =IF(AND(B13>=15000,C13>=20),"Top Performer",IF(AND(B13>=10000,C13>=15),"Strong Performer","Regular Performer")) -> Top Performer | U13: =IF(OR(B13>=15000,C13>=20),"VIP Eligible",IF(OR(B13>=10000,C13>=15),"Eligible","Not Eligible")) -> VIP Eligible | V13: =IF(E13>=3,"Critical Risk",IF(AND(E13>=2,B13<8000),"High Risk",IF(E13=1,"Medium Risk","Low Risk"))) -> Low Risk | W13: =IF(B13>=15000,"Reward",IF(B13>=10000,"Appreciate",IF(B13>=5000,"Coach","Train"))) -> Reward | X13: =IF(AND(B13>=15000,E13=0),"Excellent Customer",IF(AND(B13>=10000,E13<=1),"Good Customer",IF(B13>=5000,"Regular Customer","Low Value Customer"))) -> Excellent Customer | Y13: =IF(AND(B13>=15000,C13>=20,E13=0),"VIP + Reward",IF(AND(B13>=10000,C13>=15),"Priority Customer",IF(OR(B13>=5000,C13>=10),"Normal Customer","Needs Attention"))) -> VIP + Reward
A14: Jyothirmai | B14: 7000 | C14: 10 | D14: 0.05 | E14: 0 | F14: =IF(B14>=15000,"Very High",IF(B14>=10000,"High","Low")) -> Low | G14: =IF(B14>=15000,"A",IF(B14>=10000,"B",IF(B14>=5000,"C","D"))) -> C | H14: =IF(B14>=18000,"Excellent",IF(B14>=15000,"Very Good",IF(B14>=10000,"Good",IF(B14>=5000,"Average","Poor")))) -> Average | I14: =IF(C14>=20,"Bulk",IF(C14>=15,"Large",IF(C14>=10,"Medium","Small"))) -> Medium | J14: =IF(D14>=15%,"Very High Discount",IF(D14>=10%,"High Discount",IF(D14>=5%,"Medium Discount","Low Discount"))) -> Medium Discount | K14: =IF(E14>=3,"Critical",IF(E14=2,"High",IF(E14=1,"Medium","Low"))) -> Low | L14: =IF(B14>=15000,"Premium",IF(B14>=10000,"Gold",IF(B14>=5000,"Silver","Bronze"))) -> Silver | M14: =IF(B14>=15000,"Excellent",IF(B14>=10000,"Good",IF(B14>=7000,"Average","Needs Improvement"))) -> Average | N14: =IF(B14>=15000,15%,IF(B14>=10000,10%,IF(B14>=5000,5%,0%))) -> 0.05 | O14: =IF(B14>=15000,B14*15%,IF(B14>=10000,B14*10%,IF(B14>=5000,B14*5%,0))) -> 350 | P14: =IF(C14>=20,"Very Large Buyer",IF(C14>=15,"Large Buyer",IF(C14>=10,"Medium Buyer","Small Buyer"))) -> Medium Buyer | Q14: =IF(B14>=15000,"Priority 1",IF(B14>=10000,"Priority 2",IF(B14>=5000,"Priority 3","Priority 4"))) -> Priority 3 | R14: =IF(D14>=15%,"Review Discount",IF(D14>=10%,"Monitor",IF(D14>=5%,"Acceptable","Low Discount"))) -> Acceptable | S14: =IF(E14>=3,"Immediate Action",IF(E14=2,"Investigate",IF(E14=1,"Monitor","No Action"))) -> No Action | T14: =IF(AND(B14>=15000,C14>=20),"Top Performer",IF(AND(B14>=10000,C14>=15),"Strong Performer","Regular Performer")) -> Regular Performer | U14: =IF(OR(B14>=15000,C14>=20),"VIP Eligible",IF(OR(B14>=10000,C14>=15),"Eligible","Not Eligible")) -> Not Eligible | V14: =IF(E14>=3,"Critical Risk",IF(AND(E14>=2,B14<8000),"High Risk",IF(E14=1,"Medium Risk","Low Risk"))) -> Low Risk | W14: =IF(B14>=15000,"Reward",IF(B14>=10000,"Appreciate",IF(B14>=5000,"Coach","Train"))) -> Coach | X14: =IF(AND(B14>=15000,E14=0),"Excellent Customer",IF(AND(B14>=10000,E14<=1),"Good Customer",IF(B14>=5000,"Regular Customer","Low Value Customer"))) -> Regular Customer | Y14: =IF(AND(B14>=15000,C14>=20,E14=0),"VIP + Reward",IF(AND(B14>=10000,C14>=15),"Priority Customer",IF(OR(B14>=5000,C14>=10),"Normal Customer","Needs Attention"))) -> Normal Customer
A15: Joharika | B15: 12000 | C15: 18 | D15: 0.12 | E15: 1 | F15: =IF(B15>=15000,"Very High",IF(B15>=10000,"High","Low")) -> High | G15: =IF(B15>=15000,"A",IF(B15>=10000,"B",IF(B15>=5000,"C","D"))) -> B | H15: =IF(B15>=18000,"Excellent",IF(B15>=15000,"Very Good",IF(B15>=10000,"Good",IF(B15>=5000,"Average","Poor")))) -> Good | I15: =IF(C15>=20,"Bulk",IF(C15>=15,"Large",IF(C15>=10,"Medium","Small"))) -> Large | J15: =IF(D15>=15%,"Very High Discount",IF(D15>=10%,"High Discount",IF(D15>=5%,"Medium Discount","Low Discount"))) -> High Discount | K15: =IF(E15>=3,"Critical",IF(E15=2,"High",IF(E15=1,"Medium","Low"))) -> Medium | L15: =IF(B15>=15000,"Premium",IF(B15>=10000,"Gold",IF(B15>=5000,"Silver","Bronze"))) -> Gold | M15: =IF(B15>=15000,"Excellent",IF(B15>=10000,"Good",IF(B15>=7000,"Average","Needs Improvement"))) -> Good | N15: =IF(B15>=15000,15%,IF(B15>=10000,10%,IF(B15>=5000,5%,0%))) -> 0.1 | O15: =IF(B15>=15000,B15*15%,IF(B15>=10000,B15*10%,IF(B15>=5000,B15*5%,0))) -> 1200 | P15: =IF(C15>=20,"Very Large Buyer",IF(C15>=15,"Large Buyer",IF(C15>=10,"Medium Buyer","Small Buyer"))) -> Large Buyer | Q15: =IF(B15>=15000,"Priority 1",IF(B15>=10000,"Priority 2",IF(B15>=5000,"Priority 3","Priority 4"))) -> Priority 2 | R15: =IF(D15>=15%,"Review Discount",IF(D15>=10%,"Monitor",IF(D15>=5%,"Acceptable","Low Discount"))) -> Monitor | S15: =IF(E15>=3,"Immediate Action",IF(E15=2,"Investigate",IF(E15=1,"Monitor","No Action"))) -> Monitor | T15: =IF(AND(B15>=15000,C15>=20),"Top Performer",IF(AND(B15>=10000,C15>=15),"Strong Performer","Regular Performer")) -> Strong Performer | U15: =IF(OR(B15>=15000,C15>=20),"VIP Eligible",IF(OR(B15>=10000,C15>=15),"Eligible","Not Eligible")) -> Eligible | V15: =IF(E15>=3,"Critical Risk",IF(AND(E15>=2,B15<8000),"High Risk",IF(E15=1,"Medium Risk","Low Risk"))) -> Medium Risk | W15: =IF(B15>=15000,"Reward",IF(B15>=10000,"Appreciate",IF(B15>=5000,"Coach","Train"))) -> Appreciate | X15: =IF(AND(B15>=15000,E15=0),"Excellent Customer",IF(AND(B15>=10000,E15<=1),"Good Customer",IF(B15>=5000,"Regular Customer","Low Value Customer"))) -> Good Customer | Y15: =IF(AND(B15>=15000,C15>=20,E15=0),"VIP + Reward",IF(AND(B15>=10000,C15>=15),"Priority Customer",IF(OR(B15>=5000,C15>=10),"Normal Customer","Needs Attention"))) -> Priority Customer
A16: Lokesh | B16: 2500 | C16: 2 | D16: 0 | E16: 3 | F16: =IF(B16>=15000,"Very High",IF(B16>=10000,"High","Low")) -> Low | G16: =IF(B16>=15000,"A",IF(B16>=10000,"B",IF(B16>=5000,"C","D"))) -> D | H16: =IF(B16>=18000,"Excellent",IF(B16>=15000,"Very Good",IF(B16>=10000,"Good",IF(B16>=5000,"Average","Poor")))) -> Poor | I16: =IF(C16>=20,"Bulk",IF(C16>=15,"Large",IF(C16>=10,"Medium","Small"))) -> Small | J16: =IF(D16>=15%,"Very High Discount",IF(D16>=10%,"High Discount",IF(D16>=5%,"Medium Discount","Low Discount"))) -> Low Discount | K16: =IF(E16>=3,"Critical",IF(E16=2,"High",IF(E16=1,"Medium","Low"))) -> Critical | L16: =IF(B16>=15000,"Premium",IF(B16>=10000,"Gold",IF(B16>=5000,"Silver","Bronze"))) -> Bronze | M16: =IF(B16>=15000,"Excellent",IF(B16>=10000,"Good",IF(B16>=7000,"Average","Needs Improvement"))) -> Needs Improvement | N16: =IF(B16>=15000,15%,IF(B16>=10000,10%,IF(B16>=5000,5%,0%))) -> 0 | O16: =IF(B16>=15000,B16*15%,IF(B16>=10000,B16*10%,IF(B16>=5000,B16*5%,0))) -> 0 | P16: =IF(C16>=20,"Very Large Buyer",IF(C16>=15,"Large Buyer",IF(C16>=10,"Medium Buyer","Small Buyer"))) -> Small Buyer | Q16: =IF(B16>=15000,"Priority 1",IF(B16>=10000,"Priority 2",IF(B16>=5000,"Priority 3","Priority 4"))) -> Priority 4 | R16: =IF(D16>=15%,"Review Discount",IF(D16>=10%,"Monitor",IF(D16>=5%,"Acceptable","Low Discount"))) -> Low Discount | S16: =IF(E16>=3,"Immediate Action",IF(E16=2,"Investigate",IF(E16=1,"Monitor","No Action"))) -> Immediate Action | T16: =IF(AND(B16>=15000,C16>=20),"Top Performer",IF(AND(B16>=10000,C16>=15),"Strong Performer","Regular Performer")) -> Regular Performer | U16: =IF(OR(B16>=15000,C16>=20),"VIP Eligible",IF(OR(B16>=10000,C16>=15),"Eligible","Not Eligible")) -> Not Eligible | V16: =IF(E16>=3,"Critical Risk",IF(AND(E16>=2,B16<8000),"High Risk",IF(E16=1,"Medium Risk","Low Risk"))) -> Critical Risk | W16: =IF(B16>=15000,"Reward",IF(B16>=10000,"Appreciate",IF(B16>=5000,"Coach","Train"))) -> Train | X16: =IF(AND(B16>=15000,E16=0),"Excellent Customer",IF(AND(B16>=10000,E16<=1),"Good Customer",IF(B16>=5000,"Regular Customer","Low Value Customer"))) -> Low Value Customer | Y16: =IF(AND(B16>=15000,C16>=20,E16=0),"VIP + Reward",IF(AND(B16>=10000,C16>=15),"Priority Customer",IF(OR(B16>=5000,C16>=10),"Normal Customer","Needs Attention"))) -> Needs Attention
A17: Ramya | B17: 11000 | C17: 16 | D17: 0.1 | E17: 1 | F17: =IF(B17>=15000,"Very High",IF(B17>=10000,"High","Low")) -> High | G17: =IF(B17>=15000,"A",IF(B17>=10000,"B",IF(B17>=5000,"C","D"))) -> B | H17: =IF(B17>=18000,"Excellent",IF(B17>=15000,"Very Good",IF(B17>=10000,"Good",IF(B17>=5000,"Average","Poor")))) -> Good | I17: =IF(C17>=20,"Bulk",IF(C17>=15,"Large",IF(C17>=10,"Medium","Small"))) -> Large | J17: =IF(D17>=15%,"Very High Discount",IF(D17>=10%,"High Discount",IF(D17>=5%,"Medium Discount","Low Discount"))) -> High Discount | K17: =IF(E17>=3,"Critical",IF(E17=2,"High",IF(E17=1,"Medium","Low"))) -> Medium | L17: =IF(B17>=15000,"Premium",IF(B17>=10000,"Gold",IF(B17>=5000,"Silver","Bronze"))) -> Gold | M17: =IF(B17>=15000,"Excellent",IF(B17>=10000,"Good",IF(B17>=7000,"Average","Needs Improvement"))) -> Good | N17: =IF(B17>=15000,15%,IF(B17>=10000,10%,IF(B17>=5000,5%,0%))) -> 0.1 | O17: =IF(B17>=15000,B17*15%,IF(B17>=10000,B17*10%,IF(B17>=5000,B17*5%,0))) -> 1100 | P17: =IF(C17>=20,"Very Large Buyer",IF(C17>=15,"Large Buyer",IF(C17>=10,"Medium Buyer","Small Buyer"))) -> Large Buyer | Q17: =IF(B17>=15000,"Priority 1",IF(B17>=10000,"Priority 2",IF(B17>=5000,"Priority 3","Priority 4"))) -> Priority 2 | R17: =IF(D17>=15%,"Review Discount",IF(D17>=10%,"Monitor",IF(D17>=5%,"Acceptable","Low Discount"))) -> Monitor | S17: =IF(E17>=3,"Immediate Action",IF(E17=2,"Investigate",IF(E17=1,"Monitor","No Action"))) -> Monitor | T17: =IF(AND(B17>=15000,C17>=20),"Top Performer",IF(AND(B17>=10000,C17>=15),"Strong Performer","Regular Performer")) -> Strong Performer | U17: =IF(OR(B17>=15000,C17>=20),"VIP Eligible",IF(OR(B17>=10000,C17>=15),"Eligible","Not Eligible")) -> Eligible | V17: =IF(E17>=3,"Critical Risk",IF(AND(E17>=2,B17<8000),"High Risk",IF(E17=1,"Medium Risk","Low Risk"))) -> Medium Risk | W17: =IF(B17>=15000,"Reward",IF(B17>=10000,"Appreciate",IF(B17>=5000,"Coach","Train"))) -> Appreciate | X17: =IF(AND(B17>=15000,E17=0),"Excellent Customer",IF(AND(B17>=10000,E17<=1),"Good Customer",IF(B17>=5000,"Regular Customer","Low Value Customer"))) -> Good Customer | Y17: =IF(AND(B17>=15000,C17>=20,E17=0),"VIP + Reward",IF(AND(B17>=10000,C17>=15),"Priority Customer",IF(OR(B17>=5000,C17>=10),"Normal Customer","Needs Attention"))) -> Priority Customer
